public class CatchTest {
    public static void main(String[] args) {
        tryCatchTest5();
    }

    static void tryCatchTest1(){
        try {
            System.err.print(" 0");
            if (true) {throw new RuntimeException();}
            System.err.print(" 1");
        } catch (RuntimeException e) {     // перехватили RuntimeException
            System.err.print(" 2");
            if (true) {throw new Error();} // но бросили Error
        }
        System.err.println(" 3");          // пропускаем - уже летит Error
    }

    static void tryCatchTest2(){
        try {
            System.err.print(" 0");
            if (true) {throw new RuntimeException();}
            System.err.print(" 1");
        } catch (RuntimeException e) { // перехватили RuntimeException
            System.err.print(" 2");
            if (true) {throw e;}       // и бросили ВТОРОЙ раз ЕГО ЖЕ
        }
        System.err.println(" 3");      // пропускаем - опять летит RuntimeException
    }

    static void tryCatchTest3(){
        try {
            System.err.print(" 0");
            if (true) {throw new RuntimeException();}
            System.err.print(" 1");
        } catch (RuntimeException e) {     // перехватили RuntimeException
            System.err.print(" 2");
            if (true) {throw new Error();} // и бросили новый Error
        } catch (Error e) { // хотя есть cath по Error "ниже", но мы в него не попадаем
            System.err.print(" 3");
        }
        System.err.println(" 4");
    }

    static void tryCatchTest4(){
        try {
            System.err.print(" 0");
            if (true) {throw new RuntimeException();}
            System.err.print(" 1");
        } catch (RuntimeException e) { // перехватили RuntimeException
            System.err.print(" 2.1");
            try {
                System.err.print(" 2.2");
                if (true) {throw new Error();} // и бросили новый Error
                System.err.print(" 2.3");
            } catch (Throwable t) {            // перехватили Error
                System.err.print(" 2.4");
            }
            System.err.print(" 2.5");
        } catch (Error e) { // хотя есть cath по Error "ниже", но мы в него не попадаем
            System.err.print(" 3");
        }
        System.err.println(" 4");
    }

    static void tryCatchTest5(){
        try {
            Throwable t = new Exception(); // ссылка типа Throwable указывает на объект типа Exception
            throw t;
        } catch (RuntimeException e) {
            System.err.println("catch RuntimeException");
        } catch (Exception e) {
            System.err.println("catch Exception");
        } catch (Throwable e) {
            System.err.println("catch Throwable");
        }
        System.err.println("next statement");
    }
}
